{
 "cells": [
  {
   "cell_type": "code",
   "execution_count": 8,
   "metadata": {},
   "outputs": [],
   "source": [
    "import openai\n",
    "import os\n",
    "openai.api_key = os.getenv(\"OPENAI_API_KEY\")\n",
    "\n",
    "from openai import OpenAI\n",
    "from pathlib import Path\n",
    "\n",
    "\n"
   ]
  },
  {
   "cell_type": "markdown",
   "metadata": {},
   "source": [
    "# 创建speech"
   ]
  },
  {
   "cell_type": "code",
   "execution_count": 10,
   "metadata": {},
   "outputs": [
    {
     "data": {
      "text/plain": [
       "PosixPath('speech.mp3')"
      ]
     },
     "execution_count": 10,
     "metadata": {},
     "output_type": "execute_result"
    }
   ],
   "source": [
    "speech_file_path = Path('__file__').parent / \"speech.mp3\"\n",
    "speech_file_path"
   ]
  },
  {
   "cell_type": "code",
   "execution_count": 14,
   "metadata": {},
   "outputs": [],
   "source": [
    "response = openai.audio.speech.create(\n",
    "    model = \"tts-1\", # One of the available TTS models: tts-1 or tts-1-hd\n",
    "    voice=\"echo\", # alloy, echo, fable, onyx, nova, and shimmer.\n",
    "    input=\"The quick brown fox jumped over the lazy dog.\" # The text to generate audio for. The maximum length is 4096 characters.\n",
    ")\n",
    "\n",
    "response.stream_to_file(speech_file_path)\n"
   ]
  },
  {
   "cell_type": "markdown",
   "metadata": {},
   "source": [
    "# 创建 transcription"
   ]
  },
  {
   "cell_type": "code",
   "execution_count": 15,
   "metadata": {},
   "outputs": [
    {
     "ename": "APITimeoutError",
     "evalue": "Request timed out.",
     "output_type": "error",
     "traceback": [
      "\u001b[0;31m---------------------------------------------------------------------------\u001b[0m",
      "\u001b[0;31mTimeoutError\u001b[0m                              Traceback (most recent call last)",
      "File \u001b[0;32m~/opt/anaconda3/envs/langchain/lib/python3.10/site-packages/httpcore/_exceptions.py:8\u001b[0m, in \u001b[0;36mmap_exceptions\u001b[0;34m(map)\u001b[0m\n\u001b[1;32m      7\u001b[0m \u001b[39mtry\u001b[39;00m:\n\u001b[0;32m----> 8\u001b[0m     \u001b[39myield\u001b[39;00m\n\u001b[1;32m      9\u001b[0m \u001b[39mexcept\u001b[39;00m \u001b[39mException\u001b[39;00m \u001b[39mas\u001b[39;00m exc:  \u001b[39m# noqa: PIE786\u001b[39;00m\n",
      "File \u001b[0;32m~/opt/anaconda3/envs/langchain/lib/python3.10/site-packages/httpcore/backends/sync.py:57\u001b[0m, in \u001b[0;36mSyncStream.start_tls\u001b[0;34m(self, ssl_context, server_hostname, timeout)\u001b[0m\n\u001b[1;32m     56\u001b[0m         \u001b[39mself\u001b[39m\u001b[39m.\u001b[39mclose()\n\u001b[0;32m---> 57\u001b[0m         \u001b[39mraise\u001b[39;00m exc\n\u001b[1;32m     58\u001b[0m \u001b[39mreturn\u001b[39;00m SyncStream(sock)\n",
      "File \u001b[0;32m~/opt/anaconda3/envs/langchain/lib/python3.10/site-packages/httpcore/backends/sync.py:52\u001b[0m, in \u001b[0;36mSyncStream.start_tls\u001b[0;34m(self, ssl_context, server_hostname, timeout)\u001b[0m\n\u001b[1;32m     51\u001b[0m     \u001b[39mself\u001b[39m\u001b[39m.\u001b[39m_sock\u001b[39m.\u001b[39msettimeout(timeout)\n\u001b[0;32m---> 52\u001b[0m     sock \u001b[39m=\u001b[39m ssl_context\u001b[39m.\u001b[39;49mwrap_socket(\n\u001b[1;32m     53\u001b[0m         \u001b[39mself\u001b[39;49m\u001b[39m.\u001b[39;49m_sock, server_hostname\u001b[39m=\u001b[39;49mserver_hostname\n\u001b[1;32m     54\u001b[0m     )\n\u001b[1;32m     55\u001b[0m \u001b[39mexcept\u001b[39;00m \u001b[39mException\u001b[39;00m \u001b[39mas\u001b[39;00m exc:  \u001b[39m# pragma: nocover\u001b[39;00m\n",
      "File \u001b[0;32m~/opt/anaconda3/envs/langchain/lib/python3.10/ssl.py:513\u001b[0m, in \u001b[0;36mSSLContext.wrap_socket\u001b[0;34m(self, sock, server_side, do_handshake_on_connect, suppress_ragged_eofs, server_hostname, session)\u001b[0m\n\u001b[1;32m    507\u001b[0m \u001b[39mdef\u001b[39;00m \u001b[39mwrap_socket\u001b[39m(\u001b[39mself\u001b[39m, sock, server_side\u001b[39m=\u001b[39m\u001b[39mFalse\u001b[39;00m,\n\u001b[1;32m    508\u001b[0m                 do_handshake_on_connect\u001b[39m=\u001b[39m\u001b[39mTrue\u001b[39;00m,\n\u001b[1;32m    509\u001b[0m                 suppress_ragged_eofs\u001b[39m=\u001b[39m\u001b[39mTrue\u001b[39;00m,\n\u001b[1;32m    510\u001b[0m                 server_hostname\u001b[39m=\u001b[39m\u001b[39mNone\u001b[39;00m, session\u001b[39m=\u001b[39m\u001b[39mNone\u001b[39;00m):\n\u001b[1;32m    511\u001b[0m     \u001b[39m# SSLSocket class handles server_hostname encoding before it calls\u001b[39;00m\n\u001b[1;32m    512\u001b[0m     \u001b[39m# ctx._wrap_socket()\u001b[39;00m\n\u001b[0;32m--> 513\u001b[0m     \u001b[39mreturn\u001b[39;00m \u001b[39mself\u001b[39;49m\u001b[39m.\u001b[39;49msslsocket_class\u001b[39m.\u001b[39;49m_create(\n\u001b[1;32m    514\u001b[0m         sock\u001b[39m=\u001b[39;49msock,\n\u001b[1;32m    515\u001b[0m         server_side\u001b[39m=\u001b[39;49mserver_side,\n\u001b[1;32m    516\u001b[0m         do_handshake_on_connect\u001b[39m=\u001b[39;49mdo_handshake_on_connect,\n\u001b[1;32m    517\u001b[0m         suppress_ragged_eofs\u001b[39m=\u001b[39;49msuppress_ragged_eofs,\n\u001b[1;32m    518\u001b[0m         server_hostname\u001b[39m=\u001b[39;49mserver_hostname,\n\u001b[1;32m    519\u001b[0m         context\u001b[39m=\u001b[39;49m\u001b[39mself\u001b[39;49m,\n\u001b[1;32m    520\u001b[0m         session\u001b[39m=\u001b[39;49msession\n\u001b[1;32m    521\u001b[0m     )\n",
      "File \u001b[0;32m~/opt/anaconda3/envs/langchain/lib/python3.10/ssl.py:1071\u001b[0m, in \u001b[0;36mSSLSocket._create\u001b[0;34m(cls, sock, server_side, do_handshake_on_connect, suppress_ragged_eofs, server_hostname, context, session)\u001b[0m\n\u001b[1;32m   1070\u001b[0m             \u001b[39mraise\u001b[39;00m \u001b[39mValueError\u001b[39;00m(\u001b[39m\"\u001b[39m\u001b[39mdo_handshake_on_connect should not be specified for non-blocking sockets\u001b[39m\u001b[39m\"\u001b[39m)\n\u001b[0;32m-> 1071\u001b[0m         \u001b[39mself\u001b[39;49m\u001b[39m.\u001b[39;49mdo_handshake()\n\u001b[1;32m   1072\u001b[0m \u001b[39mexcept\u001b[39;00m (\u001b[39mOSError\u001b[39;00m, \u001b[39mValueError\u001b[39;00m):\n",
      "File \u001b[0;32m~/opt/anaconda3/envs/langchain/lib/python3.10/ssl.py:1342\u001b[0m, in \u001b[0;36mSSLSocket.do_handshake\u001b[0;34m(self, block)\u001b[0m\n\u001b[1;32m   1341\u001b[0m         \u001b[39mself\u001b[39m\u001b[39m.\u001b[39msettimeout(\u001b[39mNone\u001b[39;00m)\n\u001b[0;32m-> 1342\u001b[0m     \u001b[39mself\u001b[39;49m\u001b[39m.\u001b[39;49m_sslobj\u001b[39m.\u001b[39;49mdo_handshake()\n\u001b[1;32m   1343\u001b[0m \u001b[39mfinally\u001b[39;00m:\n",
      "\u001b[0;31mTimeoutError\u001b[0m: _ssl.c:990: The handshake operation timed out",
      "\nDuring handling of the above exception, another exception occurred:\n",
      "\u001b[0;31mConnectTimeout\u001b[0m                            Traceback (most recent call last)",
      "File \u001b[0;32m~/opt/anaconda3/envs/langchain/lib/python3.10/site-packages/httpx/_transports/default.py:60\u001b[0m, in \u001b[0;36mmap_httpcore_exceptions\u001b[0;34m()\u001b[0m\n\u001b[1;32m     59\u001b[0m \u001b[39mtry\u001b[39;00m:\n\u001b[0;32m---> 60\u001b[0m     \u001b[39myield\u001b[39;00m\n\u001b[1;32m     61\u001b[0m \u001b[39mexcept\u001b[39;00m \u001b[39mException\u001b[39;00m \u001b[39mas\u001b[39;00m exc:  \u001b[39m# noqa: PIE-786\u001b[39;00m\n",
      "File \u001b[0;32m~/opt/anaconda3/envs/langchain/lib/python3.10/site-packages/httpx/_transports/default.py:218\u001b[0m, in \u001b[0;36mHTTPTransport.handle_request\u001b[0;34m(self, request)\u001b[0m\n\u001b[1;32m    217\u001b[0m \u001b[39mwith\u001b[39;00m map_httpcore_exceptions():\n\u001b[0;32m--> 218\u001b[0m     resp \u001b[39m=\u001b[39m \u001b[39mself\u001b[39;49m\u001b[39m.\u001b[39;49m_pool\u001b[39m.\u001b[39;49mhandle_request(req)\n\u001b[1;32m    220\u001b[0m \u001b[39massert\u001b[39;00m \u001b[39misinstance\u001b[39m(resp\u001b[39m.\u001b[39mstream, typing\u001b[39m.\u001b[39mIterable)\n",
      "File \u001b[0;32m~/opt/anaconda3/envs/langchain/lib/python3.10/site-packages/httpcore/_sync/connection_pool.py:253\u001b[0m, in \u001b[0;36mConnectionPool.handle_request\u001b[0;34m(self, request)\u001b[0m\n\u001b[1;32m    252\u001b[0m     \u001b[39mself\u001b[39m\u001b[39m.\u001b[39mresponse_closed(status)\n\u001b[0;32m--> 253\u001b[0m     \u001b[39mraise\u001b[39;00m exc\n\u001b[1;32m    254\u001b[0m \u001b[39melse\u001b[39;00m:\n",
      "File \u001b[0;32m~/opt/anaconda3/envs/langchain/lib/python3.10/site-packages/httpcore/_sync/connection_pool.py:237\u001b[0m, in \u001b[0;36mConnectionPool.handle_request\u001b[0;34m(self, request)\u001b[0m\n\u001b[1;32m    236\u001b[0m \u001b[39mtry\u001b[39;00m:\n\u001b[0;32m--> 237\u001b[0m     response \u001b[39m=\u001b[39m connection\u001b[39m.\u001b[39;49mhandle_request(request)\n\u001b[1;32m    238\u001b[0m \u001b[39mexcept\u001b[39;00m ConnectionNotAvailable:\n\u001b[1;32m    239\u001b[0m     \u001b[39m# The ConnectionNotAvailable exception is a special case, that\u001b[39;00m\n\u001b[1;32m    240\u001b[0m     \u001b[39m# indicates we need to retry the request on a new connection.\u001b[39;00m\n\u001b[0;32m   (...)\u001b[0m\n\u001b[1;32m    244\u001b[0m     \u001b[39m# might end up as an HTTP/2 connection, but which actually ends\u001b[39;00m\n\u001b[1;32m    245\u001b[0m     \u001b[39m# up as HTTP/1.1.\u001b[39;00m\n",
      "File \u001b[0;32m~/opt/anaconda3/envs/langchain/lib/python3.10/site-packages/httpcore/_sync/http_proxy.py:286\u001b[0m, in \u001b[0;36mTunnelHTTPConnection.handle_request\u001b[0;34m(self, request)\u001b[0m\n\u001b[1;32m    285\u001b[0m \u001b[39mwith\u001b[39;00m Trace(\u001b[39m\"\u001b[39m\u001b[39mconnection.start_tls\u001b[39m\u001b[39m\"\u001b[39m, request, kwargs) \u001b[39mas\u001b[39;00m trace:\n\u001b[0;32m--> 286\u001b[0m     stream \u001b[39m=\u001b[39m stream\u001b[39m.\u001b[39;49mstart_tls(\u001b[39m*\u001b[39;49m\u001b[39m*\u001b[39;49mkwargs)\n\u001b[1;32m    287\u001b[0m     trace\u001b[39m.\u001b[39mreturn_value \u001b[39m=\u001b[39m stream\n",
      "File \u001b[0;32m~/opt/anaconda3/envs/langchain/lib/python3.10/site-packages/httpcore/backends/sync.py:49\u001b[0m, in \u001b[0;36mSyncStream.start_tls\u001b[0;34m(self, ssl_context, server_hostname, timeout)\u001b[0m\n\u001b[1;32m     48\u001b[0m exc_map \u001b[39m=\u001b[39m {socket\u001b[39m.\u001b[39mtimeout: ConnectTimeout, socket\u001b[39m.\u001b[39merror: ConnectError}\n\u001b[0;32m---> 49\u001b[0m \u001b[39mwith\u001b[39;00m map_exceptions(exc_map):\n\u001b[1;32m     50\u001b[0m     \u001b[39mtry\u001b[39;00m:\n",
      "File \u001b[0;32m~/opt/anaconda3/envs/langchain/lib/python3.10/contextlib.py:153\u001b[0m, in \u001b[0;36m_GeneratorContextManager.__exit__\u001b[0;34m(self, typ, value, traceback)\u001b[0m\n\u001b[1;32m    152\u001b[0m \u001b[39mtry\u001b[39;00m:\n\u001b[0;32m--> 153\u001b[0m     \u001b[39mself\u001b[39;49m\u001b[39m.\u001b[39;49mgen\u001b[39m.\u001b[39;49mthrow(typ, value, traceback)\n\u001b[1;32m    154\u001b[0m \u001b[39mexcept\u001b[39;00m \u001b[39mStopIteration\u001b[39;00m \u001b[39mas\u001b[39;00m exc:\n\u001b[1;32m    155\u001b[0m     \u001b[39m# Suppress StopIteration *unless* it's the same exception that\u001b[39;00m\n\u001b[1;32m    156\u001b[0m     \u001b[39m# was passed to throw().  This prevents a StopIteration\u001b[39;00m\n\u001b[1;32m    157\u001b[0m     \u001b[39m# raised inside the \"with\" statement from being suppressed.\u001b[39;00m\n",
      "File \u001b[0;32m~/opt/anaconda3/envs/langchain/lib/python3.10/site-packages/httpcore/_exceptions.py:12\u001b[0m, in \u001b[0;36mmap_exceptions\u001b[0;34m(map)\u001b[0m\n\u001b[1;32m     11\u001b[0m     \u001b[39mif\u001b[39;00m \u001b[39misinstance\u001b[39m(exc, from_exc):\n\u001b[0;32m---> 12\u001b[0m         \u001b[39mraise\u001b[39;00m to_exc(exc)\n\u001b[1;32m     13\u001b[0m \u001b[39mraise\u001b[39;00m\n",
      "\u001b[0;31mConnectTimeout\u001b[0m: _ssl.c:990: The handshake operation timed out",
      "\nThe above exception was the direct cause of the following exception:\n",
      "\u001b[0;31mConnectTimeout\u001b[0m                            Traceback (most recent call last)",
      "File \u001b[0;32m~/opt/anaconda3/envs/langchain/lib/python3.10/site-packages/openai/_base_client.py:858\u001b[0m, in \u001b[0;36mSyncAPIClient._request\u001b[0;34m(self, cast_to, options, remaining_retries, stream, stream_cls)\u001b[0m\n\u001b[1;32m    857\u001b[0m \u001b[39mtry\u001b[39;00m:\n\u001b[0;32m--> 858\u001b[0m     response \u001b[39m=\u001b[39m \u001b[39mself\u001b[39;49m\u001b[39m.\u001b[39;49m_client\u001b[39m.\u001b[39;49msend(request, auth\u001b[39m=\u001b[39;49m\u001b[39mself\u001b[39;49m\u001b[39m.\u001b[39;49mcustom_auth, stream\u001b[39m=\u001b[39;49mstream)\n\u001b[1;32m    859\u001b[0m     log\u001b[39m.\u001b[39mdebug(\n\u001b[1;32m    860\u001b[0m         \u001b[39m'\u001b[39m\u001b[39mHTTP Request: \u001b[39m\u001b[39m%s\u001b[39;00m\u001b[39m \u001b[39m\u001b[39m%s\u001b[39;00m\u001b[39m \u001b[39m\u001b[39m\"\u001b[39m\u001b[39m%i\u001b[39;00m\u001b[39m \u001b[39m\u001b[39m%s\u001b[39;00m\u001b[39m\"\u001b[39m\u001b[39m'\u001b[39m, request\u001b[39m.\u001b[39mmethod, request\u001b[39m.\u001b[39murl, response\u001b[39m.\u001b[39mstatus_code, response\u001b[39m.\u001b[39mreason_phrase\n\u001b[1;32m    861\u001b[0m     )\n",
      "File \u001b[0;32m~/opt/anaconda3/envs/langchain/lib/python3.10/site-packages/httpx/_client.py:902\u001b[0m, in \u001b[0;36mClient.send\u001b[0;34m(self, request, stream, auth, follow_redirects)\u001b[0m\n\u001b[1;32m    900\u001b[0m auth \u001b[39m=\u001b[39m \u001b[39mself\u001b[39m\u001b[39m.\u001b[39m_build_request_auth(request, auth)\n\u001b[0;32m--> 902\u001b[0m response \u001b[39m=\u001b[39m \u001b[39mself\u001b[39;49m\u001b[39m.\u001b[39;49m_send_handling_auth(\n\u001b[1;32m    903\u001b[0m     request,\n\u001b[1;32m    904\u001b[0m     auth\u001b[39m=\u001b[39;49mauth,\n\u001b[1;32m    905\u001b[0m     follow_redirects\u001b[39m=\u001b[39;49mfollow_redirects,\n\u001b[1;32m    906\u001b[0m     history\u001b[39m=\u001b[39;49m[],\n\u001b[1;32m    907\u001b[0m )\n\u001b[1;32m    908\u001b[0m \u001b[39mtry\u001b[39;00m:\n",
      "File \u001b[0;32m~/opt/anaconda3/envs/langchain/lib/python3.10/site-packages/httpx/_client.py:930\u001b[0m, in \u001b[0;36mClient._send_handling_auth\u001b[0;34m(self, request, auth, follow_redirects, history)\u001b[0m\n\u001b[1;32m    929\u001b[0m \u001b[39mwhile\u001b[39;00m \u001b[39mTrue\u001b[39;00m:\n\u001b[0;32m--> 930\u001b[0m     response \u001b[39m=\u001b[39m \u001b[39mself\u001b[39;49m\u001b[39m.\u001b[39;49m_send_handling_redirects(\n\u001b[1;32m    931\u001b[0m         request,\n\u001b[1;32m    932\u001b[0m         follow_redirects\u001b[39m=\u001b[39;49mfollow_redirects,\n\u001b[1;32m    933\u001b[0m         history\u001b[39m=\u001b[39;49mhistory,\n\u001b[1;32m    934\u001b[0m     )\n\u001b[1;32m    935\u001b[0m     \u001b[39mtry\u001b[39;00m:\n",
      "File \u001b[0;32m~/opt/anaconda3/envs/langchain/lib/python3.10/site-packages/httpx/_client.py:967\u001b[0m, in \u001b[0;36mClient._send_handling_redirects\u001b[0;34m(self, request, follow_redirects, history)\u001b[0m\n\u001b[1;32m    965\u001b[0m     hook(request)\n\u001b[0;32m--> 967\u001b[0m response \u001b[39m=\u001b[39m \u001b[39mself\u001b[39;49m\u001b[39m.\u001b[39;49m_send_single_request(request)\n\u001b[1;32m    968\u001b[0m \u001b[39mtry\u001b[39;00m:\n",
      "File \u001b[0;32m~/opt/anaconda3/envs/langchain/lib/python3.10/site-packages/httpx/_client.py:1003\u001b[0m, in \u001b[0;36mClient._send_single_request\u001b[0;34m(self, request)\u001b[0m\n\u001b[1;32m   1002\u001b[0m \u001b[39mwith\u001b[39;00m request_context(request\u001b[39m=\u001b[39mrequest):\n\u001b[0;32m-> 1003\u001b[0m     response \u001b[39m=\u001b[39m transport\u001b[39m.\u001b[39;49mhandle_request(request)\n\u001b[1;32m   1005\u001b[0m \u001b[39massert\u001b[39;00m \u001b[39misinstance\u001b[39m(response\u001b[39m.\u001b[39mstream, SyncByteStream)\n",
      "File \u001b[0;32m~/opt/anaconda3/envs/langchain/lib/python3.10/site-packages/httpx/_transports/default.py:217\u001b[0m, in \u001b[0;36mHTTPTransport.handle_request\u001b[0;34m(self, request)\u001b[0m\n\u001b[1;32m    205\u001b[0m req \u001b[39m=\u001b[39m httpcore\u001b[39m.\u001b[39mRequest(\n\u001b[1;32m    206\u001b[0m     method\u001b[39m=\u001b[39mrequest\u001b[39m.\u001b[39mmethod,\n\u001b[1;32m    207\u001b[0m     url\u001b[39m=\u001b[39mhttpcore\u001b[39m.\u001b[39mURL(\n\u001b[0;32m   (...)\u001b[0m\n\u001b[1;32m    215\u001b[0m     extensions\u001b[39m=\u001b[39mrequest\u001b[39m.\u001b[39mextensions,\n\u001b[1;32m    216\u001b[0m )\n\u001b[0;32m--> 217\u001b[0m \u001b[39mwith\u001b[39;00m map_httpcore_exceptions():\n\u001b[1;32m    218\u001b[0m     resp \u001b[39m=\u001b[39m \u001b[39mself\u001b[39m\u001b[39m.\u001b[39m_pool\u001b[39m.\u001b[39mhandle_request(req)\n",
      "File \u001b[0;32m~/opt/anaconda3/envs/langchain/lib/python3.10/contextlib.py:153\u001b[0m, in \u001b[0;36m_GeneratorContextManager.__exit__\u001b[0;34m(self, typ, value, traceback)\u001b[0m\n\u001b[1;32m    152\u001b[0m \u001b[39mtry\u001b[39;00m:\n\u001b[0;32m--> 153\u001b[0m     \u001b[39mself\u001b[39;49m\u001b[39m.\u001b[39;49mgen\u001b[39m.\u001b[39;49mthrow(typ, value, traceback)\n\u001b[1;32m    154\u001b[0m \u001b[39mexcept\u001b[39;00m \u001b[39mStopIteration\u001b[39;00m \u001b[39mas\u001b[39;00m exc:\n\u001b[1;32m    155\u001b[0m     \u001b[39m# Suppress StopIteration *unless* it's the same exception that\u001b[39;00m\n\u001b[1;32m    156\u001b[0m     \u001b[39m# was passed to throw().  This prevents a StopIteration\u001b[39;00m\n\u001b[1;32m    157\u001b[0m     \u001b[39m# raised inside the \"with\" statement from being suppressed.\u001b[39;00m\n",
      "File \u001b[0;32m~/opt/anaconda3/envs/langchain/lib/python3.10/site-packages/httpx/_transports/default.py:77\u001b[0m, in \u001b[0;36mmap_httpcore_exceptions\u001b[0;34m()\u001b[0m\n\u001b[1;32m     76\u001b[0m message \u001b[39m=\u001b[39m \u001b[39mstr\u001b[39m(exc)\n\u001b[0;32m---> 77\u001b[0m \u001b[39mraise\u001b[39;00m mapped_exc(message) \u001b[39mfrom\u001b[39;00m \u001b[39mexc\u001b[39;00m\n",
      "\u001b[0;31mConnectTimeout\u001b[0m: _ssl.c:990: The handshake operation timed out",
      "\nDuring handling of the above exception, another exception occurred:\n",
      "\u001b[0;31mTimeoutError\u001b[0m                              Traceback (most recent call last)",
      "File \u001b[0;32m~/opt/anaconda3/envs/langchain/lib/python3.10/site-packages/httpcore/_exceptions.py:8\u001b[0m, in \u001b[0;36mmap_exceptions\u001b[0;34m(map)\u001b[0m\n\u001b[1;32m      7\u001b[0m \u001b[39mtry\u001b[39;00m:\n\u001b[0;32m----> 8\u001b[0m     \u001b[39myield\u001b[39;00m\n\u001b[1;32m      9\u001b[0m \u001b[39mexcept\u001b[39;00m \u001b[39mException\u001b[39;00m \u001b[39mas\u001b[39;00m exc:  \u001b[39m# noqa: PIE786\u001b[39;00m\n",
      "File \u001b[0;32m~/opt/anaconda3/envs/langchain/lib/python3.10/site-packages/httpcore/backends/sync.py:57\u001b[0m, in \u001b[0;36mSyncStream.start_tls\u001b[0;34m(self, ssl_context, server_hostname, timeout)\u001b[0m\n\u001b[1;32m     56\u001b[0m         \u001b[39mself\u001b[39m\u001b[39m.\u001b[39mclose()\n\u001b[0;32m---> 57\u001b[0m         \u001b[39mraise\u001b[39;00m exc\n\u001b[1;32m     58\u001b[0m \u001b[39mreturn\u001b[39;00m SyncStream(sock)\n",
      "File \u001b[0;32m~/opt/anaconda3/envs/langchain/lib/python3.10/site-packages/httpcore/backends/sync.py:52\u001b[0m, in \u001b[0;36mSyncStream.start_tls\u001b[0;34m(self, ssl_context, server_hostname, timeout)\u001b[0m\n\u001b[1;32m     51\u001b[0m     \u001b[39mself\u001b[39m\u001b[39m.\u001b[39m_sock\u001b[39m.\u001b[39msettimeout(timeout)\n\u001b[0;32m---> 52\u001b[0m     sock \u001b[39m=\u001b[39m ssl_context\u001b[39m.\u001b[39;49mwrap_socket(\n\u001b[1;32m     53\u001b[0m         \u001b[39mself\u001b[39;49m\u001b[39m.\u001b[39;49m_sock, server_hostname\u001b[39m=\u001b[39;49mserver_hostname\n\u001b[1;32m     54\u001b[0m     )\n\u001b[1;32m     55\u001b[0m \u001b[39mexcept\u001b[39;00m \u001b[39mException\u001b[39;00m \u001b[39mas\u001b[39;00m exc:  \u001b[39m# pragma: nocover\u001b[39;00m\n",
      "File \u001b[0;32m~/opt/anaconda3/envs/langchain/lib/python3.10/ssl.py:513\u001b[0m, in \u001b[0;36mSSLContext.wrap_socket\u001b[0;34m(self, sock, server_side, do_handshake_on_connect, suppress_ragged_eofs, server_hostname, session)\u001b[0m\n\u001b[1;32m    507\u001b[0m \u001b[39mdef\u001b[39;00m \u001b[39mwrap_socket\u001b[39m(\u001b[39mself\u001b[39m, sock, server_side\u001b[39m=\u001b[39m\u001b[39mFalse\u001b[39;00m,\n\u001b[1;32m    508\u001b[0m                 do_handshake_on_connect\u001b[39m=\u001b[39m\u001b[39mTrue\u001b[39;00m,\n\u001b[1;32m    509\u001b[0m                 suppress_ragged_eofs\u001b[39m=\u001b[39m\u001b[39mTrue\u001b[39;00m,\n\u001b[1;32m    510\u001b[0m                 server_hostname\u001b[39m=\u001b[39m\u001b[39mNone\u001b[39;00m, session\u001b[39m=\u001b[39m\u001b[39mNone\u001b[39;00m):\n\u001b[1;32m    511\u001b[0m     \u001b[39m# SSLSocket class handles server_hostname encoding before it calls\u001b[39;00m\n\u001b[1;32m    512\u001b[0m     \u001b[39m# ctx._wrap_socket()\u001b[39;00m\n\u001b[0;32m--> 513\u001b[0m     \u001b[39mreturn\u001b[39;00m \u001b[39mself\u001b[39;49m\u001b[39m.\u001b[39;49msslsocket_class\u001b[39m.\u001b[39;49m_create(\n\u001b[1;32m    514\u001b[0m         sock\u001b[39m=\u001b[39;49msock,\n\u001b[1;32m    515\u001b[0m         server_side\u001b[39m=\u001b[39;49mserver_side,\n\u001b[1;32m    516\u001b[0m         do_handshake_on_connect\u001b[39m=\u001b[39;49mdo_handshake_on_connect,\n\u001b[1;32m    517\u001b[0m         suppress_ragged_eofs\u001b[39m=\u001b[39;49msuppress_ragged_eofs,\n\u001b[1;32m    518\u001b[0m         server_hostname\u001b[39m=\u001b[39;49mserver_hostname,\n\u001b[1;32m    519\u001b[0m         context\u001b[39m=\u001b[39;49m\u001b[39mself\u001b[39;49m,\n\u001b[1;32m    520\u001b[0m         session\u001b[39m=\u001b[39;49msession\n\u001b[1;32m    521\u001b[0m     )\n",
      "File \u001b[0;32m~/opt/anaconda3/envs/langchain/lib/python3.10/ssl.py:1071\u001b[0m, in \u001b[0;36mSSLSocket._create\u001b[0;34m(cls, sock, server_side, do_handshake_on_connect, suppress_ragged_eofs, server_hostname, context, session)\u001b[0m\n\u001b[1;32m   1070\u001b[0m             \u001b[39mraise\u001b[39;00m \u001b[39mValueError\u001b[39;00m(\u001b[39m\"\u001b[39m\u001b[39mdo_handshake_on_connect should not be specified for non-blocking sockets\u001b[39m\u001b[39m\"\u001b[39m)\n\u001b[0;32m-> 1071\u001b[0m         \u001b[39mself\u001b[39;49m\u001b[39m.\u001b[39;49mdo_handshake()\n\u001b[1;32m   1072\u001b[0m \u001b[39mexcept\u001b[39;00m (\u001b[39mOSError\u001b[39;00m, \u001b[39mValueError\u001b[39;00m):\n",
      "File \u001b[0;32m~/opt/anaconda3/envs/langchain/lib/python3.10/ssl.py:1342\u001b[0m, in \u001b[0;36mSSLSocket.do_handshake\u001b[0;34m(self, block)\u001b[0m\n\u001b[1;32m   1341\u001b[0m         \u001b[39mself\u001b[39m\u001b[39m.\u001b[39msettimeout(\u001b[39mNone\u001b[39;00m)\n\u001b[0;32m-> 1342\u001b[0m     \u001b[39mself\u001b[39;49m\u001b[39m.\u001b[39;49m_sslobj\u001b[39m.\u001b[39;49mdo_handshake()\n\u001b[1;32m   1343\u001b[0m \u001b[39mfinally\u001b[39;00m:\n",
      "\u001b[0;31mTimeoutError\u001b[0m: _ssl.c:990: The handshake operation timed out",
      "\nDuring handling of the above exception, another exception occurred:\n",
      "\u001b[0;31mConnectTimeout\u001b[0m                            Traceback (most recent call last)",
      "File \u001b[0;32m~/opt/anaconda3/envs/langchain/lib/python3.10/site-packages/httpx/_transports/default.py:60\u001b[0m, in \u001b[0;36mmap_httpcore_exceptions\u001b[0;34m()\u001b[0m\n\u001b[1;32m     59\u001b[0m \u001b[39mtry\u001b[39;00m:\n\u001b[0;32m---> 60\u001b[0m     \u001b[39myield\u001b[39;00m\n\u001b[1;32m     61\u001b[0m \u001b[39mexcept\u001b[39;00m \u001b[39mException\u001b[39;00m \u001b[39mas\u001b[39;00m exc:  \u001b[39m# noqa: PIE-786\u001b[39;00m\n",
      "File \u001b[0;32m~/opt/anaconda3/envs/langchain/lib/python3.10/site-packages/httpx/_transports/default.py:218\u001b[0m, in \u001b[0;36mHTTPTransport.handle_request\u001b[0;34m(self, request)\u001b[0m\n\u001b[1;32m    217\u001b[0m \u001b[39mwith\u001b[39;00m map_httpcore_exceptions():\n\u001b[0;32m--> 218\u001b[0m     resp \u001b[39m=\u001b[39m \u001b[39mself\u001b[39;49m\u001b[39m.\u001b[39;49m_pool\u001b[39m.\u001b[39;49mhandle_request(req)\n\u001b[1;32m    220\u001b[0m \u001b[39massert\u001b[39;00m \u001b[39misinstance\u001b[39m(resp\u001b[39m.\u001b[39mstream, typing\u001b[39m.\u001b[39mIterable)\n",
      "File \u001b[0;32m~/opt/anaconda3/envs/langchain/lib/python3.10/site-packages/httpcore/_sync/connection_pool.py:253\u001b[0m, in \u001b[0;36mConnectionPool.handle_request\u001b[0;34m(self, request)\u001b[0m\n\u001b[1;32m    252\u001b[0m     \u001b[39mself\u001b[39m\u001b[39m.\u001b[39mresponse_closed(status)\n\u001b[0;32m--> 253\u001b[0m     \u001b[39mraise\u001b[39;00m exc\n\u001b[1;32m    254\u001b[0m \u001b[39melse\u001b[39;00m:\n",
      "File \u001b[0;32m~/opt/anaconda3/envs/langchain/lib/python3.10/site-packages/httpcore/_sync/connection_pool.py:237\u001b[0m, in \u001b[0;36mConnectionPool.handle_request\u001b[0;34m(self, request)\u001b[0m\n\u001b[1;32m    236\u001b[0m \u001b[39mtry\u001b[39;00m:\n\u001b[0;32m--> 237\u001b[0m     response \u001b[39m=\u001b[39m connection\u001b[39m.\u001b[39;49mhandle_request(request)\n\u001b[1;32m    238\u001b[0m \u001b[39mexcept\u001b[39;00m ConnectionNotAvailable:\n\u001b[1;32m    239\u001b[0m     \u001b[39m# The ConnectionNotAvailable exception is a special case, that\u001b[39;00m\n\u001b[1;32m    240\u001b[0m     \u001b[39m# indicates we need to retry the request on a new connection.\u001b[39;00m\n\u001b[0;32m   (...)\u001b[0m\n\u001b[1;32m    244\u001b[0m     \u001b[39m# might end up as an HTTP/2 connection, but which actually ends\u001b[39;00m\n\u001b[1;32m    245\u001b[0m     \u001b[39m# up as HTTP/1.1.\u001b[39;00m\n",
      "File \u001b[0;32m~/opt/anaconda3/envs/langchain/lib/python3.10/site-packages/httpcore/_sync/http_proxy.py:286\u001b[0m, in \u001b[0;36mTunnelHTTPConnection.handle_request\u001b[0;34m(self, request)\u001b[0m\n\u001b[1;32m    285\u001b[0m \u001b[39mwith\u001b[39;00m Trace(\u001b[39m\"\u001b[39m\u001b[39mconnection.start_tls\u001b[39m\u001b[39m\"\u001b[39m, request, kwargs) \u001b[39mas\u001b[39;00m trace:\n\u001b[0;32m--> 286\u001b[0m     stream \u001b[39m=\u001b[39m stream\u001b[39m.\u001b[39;49mstart_tls(\u001b[39m*\u001b[39;49m\u001b[39m*\u001b[39;49mkwargs)\n\u001b[1;32m    287\u001b[0m     trace\u001b[39m.\u001b[39mreturn_value \u001b[39m=\u001b[39m stream\n",
      "File \u001b[0;32m~/opt/anaconda3/envs/langchain/lib/python3.10/site-packages/httpcore/backends/sync.py:49\u001b[0m, in \u001b[0;36mSyncStream.start_tls\u001b[0;34m(self, ssl_context, server_hostname, timeout)\u001b[0m\n\u001b[1;32m     48\u001b[0m exc_map \u001b[39m=\u001b[39m {socket\u001b[39m.\u001b[39mtimeout: ConnectTimeout, socket\u001b[39m.\u001b[39merror: ConnectError}\n\u001b[0;32m---> 49\u001b[0m \u001b[39mwith\u001b[39;00m map_exceptions(exc_map):\n\u001b[1;32m     50\u001b[0m     \u001b[39mtry\u001b[39;00m:\n",
      "File \u001b[0;32m~/opt/anaconda3/envs/langchain/lib/python3.10/contextlib.py:153\u001b[0m, in \u001b[0;36m_GeneratorContextManager.__exit__\u001b[0;34m(self, typ, value, traceback)\u001b[0m\n\u001b[1;32m    152\u001b[0m \u001b[39mtry\u001b[39;00m:\n\u001b[0;32m--> 153\u001b[0m     \u001b[39mself\u001b[39;49m\u001b[39m.\u001b[39;49mgen\u001b[39m.\u001b[39;49mthrow(typ, value, traceback)\n\u001b[1;32m    154\u001b[0m \u001b[39mexcept\u001b[39;00m \u001b[39mStopIteration\u001b[39;00m \u001b[39mas\u001b[39;00m exc:\n\u001b[1;32m    155\u001b[0m     \u001b[39m# Suppress StopIteration *unless* it's the same exception that\u001b[39;00m\n\u001b[1;32m    156\u001b[0m     \u001b[39m# was passed to throw().  This prevents a StopIteration\u001b[39;00m\n\u001b[1;32m    157\u001b[0m     \u001b[39m# raised inside the \"with\" statement from being suppressed.\u001b[39;00m\n",
      "File \u001b[0;32m~/opt/anaconda3/envs/langchain/lib/python3.10/site-packages/httpcore/_exceptions.py:12\u001b[0m, in \u001b[0;36mmap_exceptions\u001b[0;34m(map)\u001b[0m\n\u001b[1;32m     11\u001b[0m     \u001b[39mif\u001b[39;00m \u001b[39misinstance\u001b[39m(exc, from_exc):\n\u001b[0;32m---> 12\u001b[0m         \u001b[39mraise\u001b[39;00m to_exc(exc)\n\u001b[1;32m     13\u001b[0m \u001b[39mraise\u001b[39;00m\n",
      "\u001b[0;31mConnectTimeout\u001b[0m: _ssl.c:990: The handshake operation timed out",
      "\nThe above exception was the direct cause of the following exception:\n",
      "\u001b[0;31mConnectTimeout\u001b[0m                            Traceback (most recent call last)",
      "File \u001b[0;32m~/opt/anaconda3/envs/langchain/lib/python3.10/site-packages/openai/_base_client.py:858\u001b[0m, in \u001b[0;36mSyncAPIClient._request\u001b[0;34m(self, cast_to, options, remaining_retries, stream, stream_cls)\u001b[0m\n\u001b[1;32m    857\u001b[0m \u001b[39mtry\u001b[39;00m:\n\u001b[0;32m--> 858\u001b[0m     response \u001b[39m=\u001b[39m \u001b[39mself\u001b[39;49m\u001b[39m.\u001b[39;49m_client\u001b[39m.\u001b[39;49msend(request, auth\u001b[39m=\u001b[39;49m\u001b[39mself\u001b[39;49m\u001b[39m.\u001b[39;49mcustom_auth, stream\u001b[39m=\u001b[39;49mstream)\n\u001b[1;32m    859\u001b[0m     log\u001b[39m.\u001b[39mdebug(\n\u001b[1;32m    860\u001b[0m         \u001b[39m'\u001b[39m\u001b[39mHTTP Request: \u001b[39m\u001b[39m%s\u001b[39;00m\u001b[39m \u001b[39m\u001b[39m%s\u001b[39;00m\u001b[39m \u001b[39m\u001b[39m\"\u001b[39m\u001b[39m%i\u001b[39;00m\u001b[39m \u001b[39m\u001b[39m%s\u001b[39;00m\u001b[39m\"\u001b[39m\u001b[39m'\u001b[39m, request\u001b[39m.\u001b[39mmethod, request\u001b[39m.\u001b[39murl, response\u001b[39m.\u001b[39mstatus_code, response\u001b[39m.\u001b[39mreason_phrase\n\u001b[1;32m    861\u001b[0m     )\n",
      "File \u001b[0;32m~/opt/anaconda3/envs/langchain/lib/python3.10/site-packages/httpx/_client.py:902\u001b[0m, in \u001b[0;36mClient.send\u001b[0;34m(self, request, stream, auth, follow_redirects)\u001b[0m\n\u001b[1;32m    900\u001b[0m auth \u001b[39m=\u001b[39m \u001b[39mself\u001b[39m\u001b[39m.\u001b[39m_build_request_auth(request, auth)\n\u001b[0;32m--> 902\u001b[0m response \u001b[39m=\u001b[39m \u001b[39mself\u001b[39;49m\u001b[39m.\u001b[39;49m_send_handling_auth(\n\u001b[1;32m    903\u001b[0m     request,\n\u001b[1;32m    904\u001b[0m     auth\u001b[39m=\u001b[39;49mauth,\n\u001b[1;32m    905\u001b[0m     follow_redirects\u001b[39m=\u001b[39;49mfollow_redirects,\n\u001b[1;32m    906\u001b[0m     history\u001b[39m=\u001b[39;49m[],\n\u001b[1;32m    907\u001b[0m )\n\u001b[1;32m    908\u001b[0m \u001b[39mtry\u001b[39;00m:\n",
      "File \u001b[0;32m~/opt/anaconda3/envs/langchain/lib/python3.10/site-packages/httpx/_client.py:930\u001b[0m, in \u001b[0;36mClient._send_handling_auth\u001b[0;34m(self, request, auth, follow_redirects, history)\u001b[0m\n\u001b[1;32m    929\u001b[0m \u001b[39mwhile\u001b[39;00m \u001b[39mTrue\u001b[39;00m:\n\u001b[0;32m--> 930\u001b[0m     response \u001b[39m=\u001b[39m \u001b[39mself\u001b[39;49m\u001b[39m.\u001b[39;49m_send_handling_redirects(\n\u001b[1;32m    931\u001b[0m         request,\n\u001b[1;32m    932\u001b[0m         follow_redirects\u001b[39m=\u001b[39;49mfollow_redirects,\n\u001b[1;32m    933\u001b[0m         history\u001b[39m=\u001b[39;49mhistory,\n\u001b[1;32m    934\u001b[0m     )\n\u001b[1;32m    935\u001b[0m     \u001b[39mtry\u001b[39;00m:\n",
      "File \u001b[0;32m~/opt/anaconda3/envs/langchain/lib/python3.10/site-packages/httpx/_client.py:967\u001b[0m, in \u001b[0;36mClient._send_handling_redirects\u001b[0;34m(self, request, follow_redirects, history)\u001b[0m\n\u001b[1;32m    965\u001b[0m     hook(request)\n\u001b[0;32m--> 967\u001b[0m response \u001b[39m=\u001b[39m \u001b[39mself\u001b[39;49m\u001b[39m.\u001b[39;49m_send_single_request(request)\n\u001b[1;32m    968\u001b[0m \u001b[39mtry\u001b[39;00m:\n",
      "File \u001b[0;32m~/opt/anaconda3/envs/langchain/lib/python3.10/site-packages/httpx/_client.py:1003\u001b[0m, in \u001b[0;36mClient._send_single_request\u001b[0;34m(self, request)\u001b[0m\n\u001b[1;32m   1002\u001b[0m \u001b[39mwith\u001b[39;00m request_context(request\u001b[39m=\u001b[39mrequest):\n\u001b[0;32m-> 1003\u001b[0m     response \u001b[39m=\u001b[39m transport\u001b[39m.\u001b[39;49mhandle_request(request)\n\u001b[1;32m   1005\u001b[0m \u001b[39massert\u001b[39;00m \u001b[39misinstance\u001b[39m(response\u001b[39m.\u001b[39mstream, SyncByteStream)\n",
      "File \u001b[0;32m~/opt/anaconda3/envs/langchain/lib/python3.10/site-packages/httpx/_transports/default.py:217\u001b[0m, in \u001b[0;36mHTTPTransport.handle_request\u001b[0;34m(self, request)\u001b[0m\n\u001b[1;32m    205\u001b[0m req \u001b[39m=\u001b[39m httpcore\u001b[39m.\u001b[39mRequest(\n\u001b[1;32m    206\u001b[0m     method\u001b[39m=\u001b[39mrequest\u001b[39m.\u001b[39mmethod,\n\u001b[1;32m    207\u001b[0m     url\u001b[39m=\u001b[39mhttpcore\u001b[39m.\u001b[39mURL(\n\u001b[0;32m   (...)\u001b[0m\n\u001b[1;32m    215\u001b[0m     extensions\u001b[39m=\u001b[39mrequest\u001b[39m.\u001b[39mextensions,\n\u001b[1;32m    216\u001b[0m )\n\u001b[0;32m--> 217\u001b[0m \u001b[39mwith\u001b[39;00m map_httpcore_exceptions():\n\u001b[1;32m    218\u001b[0m     resp \u001b[39m=\u001b[39m \u001b[39mself\u001b[39m\u001b[39m.\u001b[39m_pool\u001b[39m.\u001b[39mhandle_request(req)\n",
      "File \u001b[0;32m~/opt/anaconda3/envs/langchain/lib/python3.10/contextlib.py:153\u001b[0m, in \u001b[0;36m_GeneratorContextManager.__exit__\u001b[0;34m(self, typ, value, traceback)\u001b[0m\n\u001b[1;32m    152\u001b[0m \u001b[39mtry\u001b[39;00m:\n\u001b[0;32m--> 153\u001b[0m     \u001b[39mself\u001b[39;49m\u001b[39m.\u001b[39;49mgen\u001b[39m.\u001b[39;49mthrow(typ, value, traceback)\n\u001b[1;32m    154\u001b[0m \u001b[39mexcept\u001b[39;00m \u001b[39mStopIteration\u001b[39;00m \u001b[39mas\u001b[39;00m exc:\n\u001b[1;32m    155\u001b[0m     \u001b[39m# Suppress StopIteration *unless* it's the same exception that\u001b[39;00m\n\u001b[1;32m    156\u001b[0m     \u001b[39m# was passed to throw().  This prevents a StopIteration\u001b[39;00m\n\u001b[1;32m    157\u001b[0m     \u001b[39m# raised inside the \"with\" statement from being suppressed.\u001b[39;00m\n",
      "File \u001b[0;32m~/opt/anaconda3/envs/langchain/lib/python3.10/site-packages/httpx/_transports/default.py:77\u001b[0m, in \u001b[0;36mmap_httpcore_exceptions\u001b[0;34m()\u001b[0m\n\u001b[1;32m     76\u001b[0m message \u001b[39m=\u001b[39m \u001b[39mstr\u001b[39m(exc)\n\u001b[0;32m---> 77\u001b[0m \u001b[39mraise\u001b[39;00m mapped_exc(message) \u001b[39mfrom\u001b[39;00m \u001b[39mexc\u001b[39;00m\n",
      "\u001b[0;31mConnectTimeout\u001b[0m: _ssl.c:990: The handshake operation timed out",
      "\nDuring handling of the above exception, another exception occurred:\n",
      "\u001b[0;31mTimeoutError\u001b[0m                              Traceback (most recent call last)",
      "File \u001b[0;32m~/opt/anaconda3/envs/langchain/lib/python3.10/site-packages/httpcore/_exceptions.py:8\u001b[0m, in \u001b[0;36mmap_exceptions\u001b[0;34m(map)\u001b[0m\n\u001b[1;32m      7\u001b[0m \u001b[39mtry\u001b[39;00m:\n\u001b[0;32m----> 8\u001b[0m     \u001b[39myield\u001b[39;00m\n\u001b[1;32m      9\u001b[0m \u001b[39mexcept\u001b[39;00m \u001b[39mException\u001b[39;00m \u001b[39mas\u001b[39;00m exc:  \u001b[39m# noqa: PIE786\u001b[39;00m\n",
      "File \u001b[0;32m~/opt/anaconda3/envs/langchain/lib/python3.10/site-packages/httpcore/backends/sync.py:57\u001b[0m, in \u001b[0;36mSyncStream.start_tls\u001b[0;34m(self, ssl_context, server_hostname, timeout)\u001b[0m\n\u001b[1;32m     56\u001b[0m         \u001b[39mself\u001b[39m\u001b[39m.\u001b[39mclose()\n\u001b[0;32m---> 57\u001b[0m         \u001b[39mraise\u001b[39;00m exc\n\u001b[1;32m     58\u001b[0m \u001b[39mreturn\u001b[39;00m SyncStream(sock)\n",
      "File \u001b[0;32m~/opt/anaconda3/envs/langchain/lib/python3.10/site-packages/httpcore/backends/sync.py:52\u001b[0m, in \u001b[0;36mSyncStream.start_tls\u001b[0;34m(self, ssl_context, server_hostname, timeout)\u001b[0m\n\u001b[1;32m     51\u001b[0m     \u001b[39mself\u001b[39m\u001b[39m.\u001b[39m_sock\u001b[39m.\u001b[39msettimeout(timeout)\n\u001b[0;32m---> 52\u001b[0m     sock \u001b[39m=\u001b[39m ssl_context\u001b[39m.\u001b[39;49mwrap_socket(\n\u001b[1;32m     53\u001b[0m         \u001b[39mself\u001b[39;49m\u001b[39m.\u001b[39;49m_sock, server_hostname\u001b[39m=\u001b[39;49mserver_hostname\n\u001b[1;32m     54\u001b[0m     )\n\u001b[1;32m     55\u001b[0m \u001b[39mexcept\u001b[39;00m \u001b[39mException\u001b[39;00m \u001b[39mas\u001b[39;00m exc:  \u001b[39m# pragma: nocover\u001b[39;00m\n",
      "File \u001b[0;32m~/opt/anaconda3/envs/langchain/lib/python3.10/ssl.py:513\u001b[0m, in \u001b[0;36mSSLContext.wrap_socket\u001b[0;34m(self, sock, server_side, do_handshake_on_connect, suppress_ragged_eofs, server_hostname, session)\u001b[0m\n\u001b[1;32m    507\u001b[0m \u001b[39mdef\u001b[39;00m \u001b[39mwrap_socket\u001b[39m(\u001b[39mself\u001b[39m, sock, server_side\u001b[39m=\u001b[39m\u001b[39mFalse\u001b[39;00m,\n\u001b[1;32m    508\u001b[0m                 do_handshake_on_connect\u001b[39m=\u001b[39m\u001b[39mTrue\u001b[39;00m,\n\u001b[1;32m    509\u001b[0m                 suppress_ragged_eofs\u001b[39m=\u001b[39m\u001b[39mTrue\u001b[39;00m,\n\u001b[1;32m    510\u001b[0m                 server_hostname\u001b[39m=\u001b[39m\u001b[39mNone\u001b[39;00m, session\u001b[39m=\u001b[39m\u001b[39mNone\u001b[39;00m):\n\u001b[1;32m    511\u001b[0m     \u001b[39m# SSLSocket class handles server_hostname encoding before it calls\u001b[39;00m\n\u001b[1;32m    512\u001b[0m     \u001b[39m# ctx._wrap_socket()\u001b[39;00m\n\u001b[0;32m--> 513\u001b[0m     \u001b[39mreturn\u001b[39;00m \u001b[39mself\u001b[39;49m\u001b[39m.\u001b[39;49msslsocket_class\u001b[39m.\u001b[39;49m_create(\n\u001b[1;32m    514\u001b[0m         sock\u001b[39m=\u001b[39;49msock,\n\u001b[1;32m    515\u001b[0m         server_side\u001b[39m=\u001b[39;49mserver_side,\n\u001b[1;32m    516\u001b[0m         do_handshake_on_connect\u001b[39m=\u001b[39;49mdo_handshake_on_connect,\n\u001b[1;32m    517\u001b[0m         suppress_ragged_eofs\u001b[39m=\u001b[39;49msuppress_ragged_eofs,\n\u001b[1;32m    518\u001b[0m         server_hostname\u001b[39m=\u001b[39;49mserver_hostname,\n\u001b[1;32m    519\u001b[0m         context\u001b[39m=\u001b[39;49m\u001b[39mself\u001b[39;49m,\n\u001b[1;32m    520\u001b[0m         session\u001b[39m=\u001b[39;49msession\n\u001b[1;32m    521\u001b[0m     )\n",
      "File \u001b[0;32m~/opt/anaconda3/envs/langchain/lib/python3.10/ssl.py:1071\u001b[0m, in \u001b[0;36mSSLSocket._create\u001b[0;34m(cls, sock, server_side, do_handshake_on_connect, suppress_ragged_eofs, server_hostname, context, session)\u001b[0m\n\u001b[1;32m   1070\u001b[0m             \u001b[39mraise\u001b[39;00m \u001b[39mValueError\u001b[39;00m(\u001b[39m\"\u001b[39m\u001b[39mdo_handshake_on_connect should not be specified for non-blocking sockets\u001b[39m\u001b[39m\"\u001b[39m)\n\u001b[0;32m-> 1071\u001b[0m         \u001b[39mself\u001b[39;49m\u001b[39m.\u001b[39;49mdo_handshake()\n\u001b[1;32m   1072\u001b[0m \u001b[39mexcept\u001b[39;00m (\u001b[39mOSError\u001b[39;00m, \u001b[39mValueError\u001b[39;00m):\n",
      "File \u001b[0;32m~/opt/anaconda3/envs/langchain/lib/python3.10/ssl.py:1342\u001b[0m, in \u001b[0;36mSSLSocket.do_handshake\u001b[0;34m(self, block)\u001b[0m\n\u001b[1;32m   1341\u001b[0m         \u001b[39mself\u001b[39m\u001b[39m.\u001b[39msettimeout(\u001b[39mNone\u001b[39;00m)\n\u001b[0;32m-> 1342\u001b[0m     \u001b[39mself\u001b[39;49m\u001b[39m.\u001b[39;49m_sslobj\u001b[39m.\u001b[39;49mdo_handshake()\n\u001b[1;32m   1343\u001b[0m \u001b[39mfinally\u001b[39;00m:\n",
      "\u001b[0;31mTimeoutError\u001b[0m: _ssl.c:990: The handshake operation timed out",
      "\nDuring handling of the above exception, another exception occurred:\n",
      "\u001b[0;31mConnectTimeout\u001b[0m                            Traceback (most recent call last)",
      "File \u001b[0;32m~/opt/anaconda3/envs/langchain/lib/python3.10/site-packages/httpx/_transports/default.py:60\u001b[0m, in \u001b[0;36mmap_httpcore_exceptions\u001b[0;34m()\u001b[0m\n\u001b[1;32m     59\u001b[0m \u001b[39mtry\u001b[39;00m:\n\u001b[0;32m---> 60\u001b[0m     \u001b[39myield\u001b[39;00m\n\u001b[1;32m     61\u001b[0m \u001b[39mexcept\u001b[39;00m \u001b[39mException\u001b[39;00m \u001b[39mas\u001b[39;00m exc:  \u001b[39m# noqa: PIE-786\u001b[39;00m\n",
      "File \u001b[0;32m~/opt/anaconda3/envs/langchain/lib/python3.10/site-packages/httpx/_transports/default.py:218\u001b[0m, in \u001b[0;36mHTTPTransport.handle_request\u001b[0;34m(self, request)\u001b[0m\n\u001b[1;32m    217\u001b[0m \u001b[39mwith\u001b[39;00m map_httpcore_exceptions():\n\u001b[0;32m--> 218\u001b[0m     resp \u001b[39m=\u001b[39m \u001b[39mself\u001b[39;49m\u001b[39m.\u001b[39;49m_pool\u001b[39m.\u001b[39;49mhandle_request(req)\n\u001b[1;32m    220\u001b[0m \u001b[39massert\u001b[39;00m \u001b[39misinstance\u001b[39m(resp\u001b[39m.\u001b[39mstream, typing\u001b[39m.\u001b[39mIterable)\n",
      "File \u001b[0;32m~/opt/anaconda3/envs/langchain/lib/python3.10/site-packages/httpcore/_sync/connection_pool.py:253\u001b[0m, in \u001b[0;36mConnectionPool.handle_request\u001b[0;34m(self, request)\u001b[0m\n\u001b[1;32m    252\u001b[0m     \u001b[39mself\u001b[39m\u001b[39m.\u001b[39mresponse_closed(status)\n\u001b[0;32m--> 253\u001b[0m     \u001b[39mraise\u001b[39;00m exc\n\u001b[1;32m    254\u001b[0m \u001b[39melse\u001b[39;00m:\n",
      "File \u001b[0;32m~/opt/anaconda3/envs/langchain/lib/python3.10/site-packages/httpcore/_sync/connection_pool.py:237\u001b[0m, in \u001b[0;36mConnectionPool.handle_request\u001b[0;34m(self, request)\u001b[0m\n\u001b[1;32m    236\u001b[0m \u001b[39mtry\u001b[39;00m:\n\u001b[0;32m--> 237\u001b[0m     response \u001b[39m=\u001b[39m connection\u001b[39m.\u001b[39;49mhandle_request(request)\n\u001b[1;32m    238\u001b[0m \u001b[39mexcept\u001b[39;00m ConnectionNotAvailable:\n\u001b[1;32m    239\u001b[0m     \u001b[39m# The ConnectionNotAvailable exception is a special case, that\u001b[39;00m\n\u001b[1;32m    240\u001b[0m     \u001b[39m# indicates we need to retry the request on a new connection.\u001b[39;00m\n\u001b[0;32m   (...)\u001b[0m\n\u001b[1;32m    244\u001b[0m     \u001b[39m# might end up as an HTTP/2 connection, but which actually ends\u001b[39;00m\n\u001b[1;32m    245\u001b[0m     \u001b[39m# up as HTTP/1.1.\u001b[39;00m\n",
      "File \u001b[0;32m~/opt/anaconda3/envs/langchain/lib/python3.10/site-packages/httpcore/_sync/http_proxy.py:286\u001b[0m, in \u001b[0;36mTunnelHTTPConnection.handle_request\u001b[0;34m(self, request)\u001b[0m\n\u001b[1;32m    285\u001b[0m \u001b[39mwith\u001b[39;00m Trace(\u001b[39m\"\u001b[39m\u001b[39mconnection.start_tls\u001b[39m\u001b[39m\"\u001b[39m, request, kwargs) \u001b[39mas\u001b[39;00m trace:\n\u001b[0;32m--> 286\u001b[0m     stream \u001b[39m=\u001b[39m stream\u001b[39m.\u001b[39;49mstart_tls(\u001b[39m*\u001b[39;49m\u001b[39m*\u001b[39;49mkwargs)\n\u001b[1;32m    287\u001b[0m     trace\u001b[39m.\u001b[39mreturn_value \u001b[39m=\u001b[39m stream\n",
      "File \u001b[0;32m~/opt/anaconda3/envs/langchain/lib/python3.10/site-packages/httpcore/backends/sync.py:49\u001b[0m, in \u001b[0;36mSyncStream.start_tls\u001b[0;34m(self, ssl_context, server_hostname, timeout)\u001b[0m\n\u001b[1;32m     48\u001b[0m exc_map \u001b[39m=\u001b[39m {socket\u001b[39m.\u001b[39mtimeout: ConnectTimeout, socket\u001b[39m.\u001b[39merror: ConnectError}\n\u001b[0;32m---> 49\u001b[0m \u001b[39mwith\u001b[39;00m map_exceptions(exc_map):\n\u001b[1;32m     50\u001b[0m     \u001b[39mtry\u001b[39;00m:\n",
      "File \u001b[0;32m~/opt/anaconda3/envs/langchain/lib/python3.10/contextlib.py:153\u001b[0m, in \u001b[0;36m_GeneratorContextManager.__exit__\u001b[0;34m(self, typ, value, traceback)\u001b[0m\n\u001b[1;32m    152\u001b[0m \u001b[39mtry\u001b[39;00m:\n\u001b[0;32m--> 153\u001b[0m     \u001b[39mself\u001b[39;49m\u001b[39m.\u001b[39;49mgen\u001b[39m.\u001b[39;49mthrow(typ, value, traceback)\n\u001b[1;32m    154\u001b[0m \u001b[39mexcept\u001b[39;00m \u001b[39mStopIteration\u001b[39;00m \u001b[39mas\u001b[39;00m exc:\n\u001b[1;32m    155\u001b[0m     \u001b[39m# Suppress StopIteration *unless* it's the same exception that\u001b[39;00m\n\u001b[1;32m    156\u001b[0m     \u001b[39m# was passed to throw().  This prevents a StopIteration\u001b[39;00m\n\u001b[1;32m    157\u001b[0m     \u001b[39m# raised inside the \"with\" statement from being suppressed.\u001b[39;00m\n",
      "File \u001b[0;32m~/opt/anaconda3/envs/langchain/lib/python3.10/site-packages/httpcore/_exceptions.py:12\u001b[0m, in \u001b[0;36mmap_exceptions\u001b[0;34m(map)\u001b[0m\n\u001b[1;32m     11\u001b[0m     \u001b[39mif\u001b[39;00m \u001b[39misinstance\u001b[39m(exc, from_exc):\n\u001b[0;32m---> 12\u001b[0m         \u001b[39mraise\u001b[39;00m to_exc(exc)\n\u001b[1;32m     13\u001b[0m \u001b[39mraise\u001b[39;00m\n",
      "\u001b[0;31mConnectTimeout\u001b[0m: _ssl.c:990: The handshake operation timed out",
      "\nThe above exception was the direct cause of the following exception:\n",
      "\u001b[0;31mConnectTimeout\u001b[0m                            Traceback (most recent call last)",
      "File \u001b[0;32m~/opt/anaconda3/envs/langchain/lib/python3.10/site-packages/openai/_base_client.py:858\u001b[0m, in \u001b[0;36mSyncAPIClient._request\u001b[0;34m(self, cast_to, options, remaining_retries, stream, stream_cls)\u001b[0m\n\u001b[1;32m    857\u001b[0m \u001b[39mtry\u001b[39;00m:\n\u001b[0;32m--> 858\u001b[0m     response \u001b[39m=\u001b[39m \u001b[39mself\u001b[39;49m\u001b[39m.\u001b[39;49m_client\u001b[39m.\u001b[39;49msend(request, auth\u001b[39m=\u001b[39;49m\u001b[39mself\u001b[39;49m\u001b[39m.\u001b[39;49mcustom_auth, stream\u001b[39m=\u001b[39;49mstream)\n\u001b[1;32m    859\u001b[0m     log\u001b[39m.\u001b[39mdebug(\n\u001b[1;32m    860\u001b[0m         \u001b[39m'\u001b[39m\u001b[39mHTTP Request: \u001b[39m\u001b[39m%s\u001b[39;00m\u001b[39m \u001b[39m\u001b[39m%s\u001b[39;00m\u001b[39m \u001b[39m\u001b[39m\"\u001b[39m\u001b[39m%i\u001b[39;00m\u001b[39m \u001b[39m\u001b[39m%s\u001b[39;00m\u001b[39m\"\u001b[39m\u001b[39m'\u001b[39m, request\u001b[39m.\u001b[39mmethod, request\u001b[39m.\u001b[39murl, response\u001b[39m.\u001b[39mstatus_code, response\u001b[39m.\u001b[39mreason_phrase\n\u001b[1;32m    861\u001b[0m     )\n",
      "File \u001b[0;32m~/opt/anaconda3/envs/langchain/lib/python3.10/site-packages/httpx/_client.py:902\u001b[0m, in \u001b[0;36mClient.send\u001b[0;34m(self, request, stream, auth, follow_redirects)\u001b[0m\n\u001b[1;32m    900\u001b[0m auth \u001b[39m=\u001b[39m \u001b[39mself\u001b[39m\u001b[39m.\u001b[39m_build_request_auth(request, auth)\n\u001b[0;32m--> 902\u001b[0m response \u001b[39m=\u001b[39m \u001b[39mself\u001b[39;49m\u001b[39m.\u001b[39;49m_send_handling_auth(\n\u001b[1;32m    903\u001b[0m     request,\n\u001b[1;32m    904\u001b[0m     auth\u001b[39m=\u001b[39;49mauth,\n\u001b[1;32m    905\u001b[0m     follow_redirects\u001b[39m=\u001b[39;49mfollow_redirects,\n\u001b[1;32m    906\u001b[0m     history\u001b[39m=\u001b[39;49m[],\n\u001b[1;32m    907\u001b[0m )\n\u001b[1;32m    908\u001b[0m \u001b[39mtry\u001b[39;00m:\n",
      "File \u001b[0;32m~/opt/anaconda3/envs/langchain/lib/python3.10/site-packages/httpx/_client.py:930\u001b[0m, in \u001b[0;36mClient._send_handling_auth\u001b[0;34m(self, request, auth, follow_redirects, history)\u001b[0m\n\u001b[1;32m    929\u001b[0m \u001b[39mwhile\u001b[39;00m \u001b[39mTrue\u001b[39;00m:\n\u001b[0;32m--> 930\u001b[0m     response \u001b[39m=\u001b[39m \u001b[39mself\u001b[39;49m\u001b[39m.\u001b[39;49m_send_handling_redirects(\n\u001b[1;32m    931\u001b[0m         request,\n\u001b[1;32m    932\u001b[0m         follow_redirects\u001b[39m=\u001b[39;49mfollow_redirects,\n\u001b[1;32m    933\u001b[0m         history\u001b[39m=\u001b[39;49mhistory,\n\u001b[1;32m    934\u001b[0m     )\n\u001b[1;32m    935\u001b[0m     \u001b[39mtry\u001b[39;00m:\n",
      "File \u001b[0;32m~/opt/anaconda3/envs/langchain/lib/python3.10/site-packages/httpx/_client.py:967\u001b[0m, in \u001b[0;36mClient._send_handling_redirects\u001b[0;34m(self, request, follow_redirects, history)\u001b[0m\n\u001b[1;32m    965\u001b[0m     hook(request)\n\u001b[0;32m--> 967\u001b[0m response \u001b[39m=\u001b[39m \u001b[39mself\u001b[39;49m\u001b[39m.\u001b[39;49m_send_single_request(request)\n\u001b[1;32m    968\u001b[0m \u001b[39mtry\u001b[39;00m:\n",
      "File \u001b[0;32m~/opt/anaconda3/envs/langchain/lib/python3.10/site-packages/httpx/_client.py:1003\u001b[0m, in \u001b[0;36mClient._send_single_request\u001b[0;34m(self, request)\u001b[0m\n\u001b[1;32m   1002\u001b[0m \u001b[39mwith\u001b[39;00m request_context(request\u001b[39m=\u001b[39mrequest):\n\u001b[0;32m-> 1003\u001b[0m     response \u001b[39m=\u001b[39m transport\u001b[39m.\u001b[39;49mhandle_request(request)\n\u001b[1;32m   1005\u001b[0m \u001b[39massert\u001b[39;00m \u001b[39misinstance\u001b[39m(response\u001b[39m.\u001b[39mstream, SyncByteStream)\n",
      "File \u001b[0;32m~/opt/anaconda3/envs/langchain/lib/python3.10/site-packages/httpx/_transports/default.py:217\u001b[0m, in \u001b[0;36mHTTPTransport.handle_request\u001b[0;34m(self, request)\u001b[0m\n\u001b[1;32m    205\u001b[0m req \u001b[39m=\u001b[39m httpcore\u001b[39m.\u001b[39mRequest(\n\u001b[1;32m    206\u001b[0m     method\u001b[39m=\u001b[39mrequest\u001b[39m.\u001b[39mmethod,\n\u001b[1;32m    207\u001b[0m     url\u001b[39m=\u001b[39mhttpcore\u001b[39m.\u001b[39mURL(\n\u001b[0;32m   (...)\u001b[0m\n\u001b[1;32m    215\u001b[0m     extensions\u001b[39m=\u001b[39mrequest\u001b[39m.\u001b[39mextensions,\n\u001b[1;32m    216\u001b[0m )\n\u001b[0;32m--> 217\u001b[0m \u001b[39mwith\u001b[39;00m map_httpcore_exceptions():\n\u001b[1;32m    218\u001b[0m     resp \u001b[39m=\u001b[39m \u001b[39mself\u001b[39m\u001b[39m.\u001b[39m_pool\u001b[39m.\u001b[39mhandle_request(req)\n",
      "File \u001b[0;32m~/opt/anaconda3/envs/langchain/lib/python3.10/contextlib.py:153\u001b[0m, in \u001b[0;36m_GeneratorContextManager.__exit__\u001b[0;34m(self, typ, value, traceback)\u001b[0m\n\u001b[1;32m    152\u001b[0m \u001b[39mtry\u001b[39;00m:\n\u001b[0;32m--> 153\u001b[0m     \u001b[39mself\u001b[39;49m\u001b[39m.\u001b[39;49mgen\u001b[39m.\u001b[39;49mthrow(typ, value, traceback)\n\u001b[1;32m    154\u001b[0m \u001b[39mexcept\u001b[39;00m \u001b[39mStopIteration\u001b[39;00m \u001b[39mas\u001b[39;00m exc:\n\u001b[1;32m    155\u001b[0m     \u001b[39m# Suppress StopIteration *unless* it's the same exception that\u001b[39;00m\n\u001b[1;32m    156\u001b[0m     \u001b[39m# was passed to throw().  This prevents a StopIteration\u001b[39;00m\n\u001b[1;32m    157\u001b[0m     \u001b[39m# raised inside the \"with\" statement from being suppressed.\u001b[39;00m\n",
      "File \u001b[0;32m~/opt/anaconda3/envs/langchain/lib/python3.10/site-packages/httpx/_transports/default.py:77\u001b[0m, in \u001b[0;36mmap_httpcore_exceptions\u001b[0;34m()\u001b[0m\n\u001b[1;32m     76\u001b[0m message \u001b[39m=\u001b[39m \u001b[39mstr\u001b[39m(exc)\n\u001b[0;32m---> 77\u001b[0m \u001b[39mraise\u001b[39;00m mapped_exc(message) \u001b[39mfrom\u001b[39;00m \u001b[39mexc\u001b[39;00m\n",
      "\u001b[0;31mConnectTimeout\u001b[0m: _ssl.c:990: The handshake operation timed out",
      "\nThe above exception was the direct cause of the following exception:\n",
      "\u001b[0;31mAPITimeoutError\u001b[0m                           Traceback (most recent call last)",
      "\u001b[1;32m/Users/matao/study/self_repository/openai/audio_api.ipynb 单元格 6\u001b[0m line \u001b[0;36m6\n\u001b[1;32m      <a href='vscode-notebook-cell:/Users/matao/study/self_repository/openai/audio_api.ipynb#W3sZmlsZQ%3D%3D?line=1'>2</a>\u001b[0m client \u001b[39m=\u001b[39m OpenAI()\n\u001b[1;32m      <a href='vscode-notebook-cell:/Users/matao/study/self_repository/openai/audio_api.ipynb#W3sZmlsZQ%3D%3D?line=3'>4</a>\u001b[0m audio_file \u001b[39m=\u001b[39m \u001b[39mopen\u001b[39m(\u001b[39m\"\u001b[39m\u001b[39mspeech.mp3\u001b[39m\u001b[39m\"\u001b[39m, \u001b[39m\"\u001b[39m\u001b[39mrb\u001b[39m\u001b[39m\"\u001b[39m)\n\u001b[0;32m----> <a href='vscode-notebook-cell:/Users/matao/study/self_repository/openai/audio_api.ipynb#W3sZmlsZQ%3D%3D?line=5'>6</a>\u001b[0m transcript \u001b[39m=\u001b[39m client\u001b[39m.\u001b[39;49maudio\u001b[39m.\u001b[39;49mtranscriptions\u001b[39m.\u001b[39;49mcreate(\n\u001b[1;32m      <a href='vscode-notebook-cell:/Users/matao/study/self_repository/openai/audio_api.ipynb#W3sZmlsZQ%3D%3D?line=6'>7</a>\u001b[0m     model\u001b[39m=\u001b[39;49m\u001b[39m\"\u001b[39;49m\u001b[39mwhisper-1\u001b[39;49m\u001b[39m\"\u001b[39;49m,\n\u001b[1;32m      <a href='vscode-notebook-cell:/Users/matao/study/self_repository/openai/audio_api.ipynb#W3sZmlsZQ%3D%3D?line=7'>8</a>\u001b[0m     file\u001b[39m=\u001b[39;49maudio_file\n\u001b[1;32m      <a href='vscode-notebook-cell:/Users/matao/study/self_repository/openai/audio_api.ipynb#W3sZmlsZQ%3D%3D?line=8'>9</a>\u001b[0m )\n",
      "File \u001b[0;32m~/opt/anaconda3/envs/langchain/lib/python3.10/site-packages/openai/resources/audio/transcriptions.py:99\u001b[0m, in \u001b[0;36mTranscriptions.create\u001b[0;34m(self, file, model, language, prompt, response_format, temperature, extra_headers, extra_query, extra_body, timeout)\u001b[0m\n\u001b[1;32m     93\u001b[0m \u001b[39mif\u001b[39;00m files:\n\u001b[1;32m     94\u001b[0m     \u001b[39m# It should be noted that the actual Content-Type header that will be\u001b[39;00m\n\u001b[1;32m     95\u001b[0m     \u001b[39m# sent to the server will contain a `boundary` parameter, e.g.\u001b[39;00m\n\u001b[1;32m     96\u001b[0m     \u001b[39m# multipart/form-data; boundary=---abc--\u001b[39;00m\n\u001b[1;32m     97\u001b[0m     extra_headers \u001b[39m=\u001b[39m {\u001b[39m\"\u001b[39m\u001b[39mContent-Type\u001b[39m\u001b[39m\"\u001b[39m: \u001b[39m\"\u001b[39m\u001b[39mmultipart/form-data\u001b[39m\u001b[39m\"\u001b[39m, \u001b[39m*\u001b[39m\u001b[39m*\u001b[39m(extra_headers \u001b[39mor\u001b[39;00m {})}\n\u001b[0;32m---> 99\u001b[0m \u001b[39mreturn\u001b[39;00m \u001b[39mself\u001b[39;49m\u001b[39m.\u001b[39;49m_post(\n\u001b[1;32m    100\u001b[0m     \u001b[39m\"\u001b[39;49m\u001b[39m/audio/transcriptions\u001b[39;49m\u001b[39m\"\u001b[39;49m,\n\u001b[1;32m    101\u001b[0m     body\u001b[39m=\u001b[39;49mmaybe_transform(body, transcription_create_params\u001b[39m.\u001b[39;49mTranscriptionCreateParams),\n\u001b[1;32m    102\u001b[0m     files\u001b[39m=\u001b[39;49mfiles,\n\u001b[1;32m    103\u001b[0m     options\u001b[39m=\u001b[39;49mmake_request_options(\n\u001b[1;32m    104\u001b[0m         extra_headers\u001b[39m=\u001b[39;49mextra_headers, extra_query\u001b[39m=\u001b[39;49mextra_query, extra_body\u001b[39m=\u001b[39;49mextra_body, timeout\u001b[39m=\u001b[39;49mtimeout\n\u001b[1;32m    105\u001b[0m     ),\n\u001b[1;32m    106\u001b[0m     cast_to\u001b[39m=\u001b[39;49mTranscription,\n\u001b[1;32m    107\u001b[0m )\n",
      "File \u001b[0;32m~/opt/anaconda3/envs/langchain/lib/python3.10/site-packages/openai/_base_client.py:1055\u001b[0m, in \u001b[0;36mSyncAPIClient.post\u001b[0;34m(self, path, cast_to, body, options, files, stream, stream_cls)\u001b[0m\n\u001b[1;32m   1041\u001b[0m \u001b[39mdef\u001b[39;00m \u001b[39mpost\u001b[39m(\n\u001b[1;32m   1042\u001b[0m     \u001b[39mself\u001b[39m,\n\u001b[1;32m   1043\u001b[0m     path: \u001b[39mstr\u001b[39m,\n\u001b[0;32m   (...)\u001b[0m\n\u001b[1;32m   1050\u001b[0m     stream_cls: \u001b[39mtype\u001b[39m[_StreamT] \u001b[39m|\u001b[39m \u001b[39mNone\u001b[39;00m \u001b[39m=\u001b[39m \u001b[39mNone\u001b[39;00m,\n\u001b[1;32m   1051\u001b[0m ) \u001b[39m-\u001b[39m\u001b[39m>\u001b[39m ResponseT \u001b[39m|\u001b[39m _StreamT:\n\u001b[1;32m   1052\u001b[0m     opts \u001b[39m=\u001b[39m FinalRequestOptions\u001b[39m.\u001b[39mconstruct(\n\u001b[1;32m   1053\u001b[0m         method\u001b[39m=\u001b[39m\u001b[39m\"\u001b[39m\u001b[39mpost\u001b[39m\u001b[39m\"\u001b[39m, url\u001b[39m=\u001b[39mpath, json_data\u001b[39m=\u001b[39mbody, files\u001b[39m=\u001b[39mto_httpx_files(files), \u001b[39m*\u001b[39m\u001b[39m*\u001b[39moptions\n\u001b[1;32m   1054\u001b[0m     )\n\u001b[0;32m-> 1055\u001b[0m     \u001b[39mreturn\u001b[39;00m cast(ResponseT, \u001b[39mself\u001b[39;49m\u001b[39m.\u001b[39;49mrequest(cast_to, opts, stream\u001b[39m=\u001b[39;49mstream, stream_cls\u001b[39m=\u001b[39;49mstream_cls))\n",
      "File \u001b[0;32m~/opt/anaconda3/envs/langchain/lib/python3.10/site-packages/openai/_base_client.py:834\u001b[0m, in \u001b[0;36mSyncAPIClient.request\u001b[0;34m(self, cast_to, options, remaining_retries, stream, stream_cls)\u001b[0m\n\u001b[1;32m    825\u001b[0m \u001b[39mdef\u001b[39;00m \u001b[39mrequest\u001b[39m(\n\u001b[1;32m    826\u001b[0m     \u001b[39mself\u001b[39m,\n\u001b[1;32m    827\u001b[0m     cast_to: Type[ResponseT],\n\u001b[0;32m   (...)\u001b[0m\n\u001b[1;32m    832\u001b[0m     stream_cls: \u001b[39mtype\u001b[39m[_StreamT] \u001b[39m|\u001b[39m \u001b[39mNone\u001b[39;00m \u001b[39m=\u001b[39m \u001b[39mNone\u001b[39;00m,\n\u001b[1;32m    833\u001b[0m ) \u001b[39m-\u001b[39m\u001b[39m>\u001b[39m ResponseT \u001b[39m|\u001b[39m _StreamT:\n\u001b[0;32m--> 834\u001b[0m     \u001b[39mreturn\u001b[39;00m \u001b[39mself\u001b[39;49m\u001b[39m.\u001b[39;49m_request(\n\u001b[1;32m    835\u001b[0m         cast_to\u001b[39m=\u001b[39;49mcast_to,\n\u001b[1;32m    836\u001b[0m         options\u001b[39m=\u001b[39;49moptions,\n\u001b[1;32m    837\u001b[0m         stream\u001b[39m=\u001b[39;49mstream,\n\u001b[1;32m    838\u001b[0m         stream_cls\u001b[39m=\u001b[39;49mstream_cls,\n\u001b[1;32m    839\u001b[0m         remaining_retries\u001b[39m=\u001b[39;49mremaining_retries,\n\u001b[1;32m    840\u001b[0m     )\n",
      "File \u001b[0;32m~/opt/anaconda3/envs/langchain/lib/python3.10/site-packages/openai/_base_client.py:880\u001b[0m, in \u001b[0;36mSyncAPIClient._request\u001b[0;34m(self, cast_to, options, remaining_retries, stream, stream_cls)\u001b[0m\n\u001b[1;32m    878\u001b[0m \u001b[39mexcept\u001b[39;00m httpx\u001b[39m.\u001b[39mTimeoutException \u001b[39mas\u001b[39;00m err:\n\u001b[1;32m    879\u001b[0m     \u001b[39mif\u001b[39;00m retries \u001b[39m>\u001b[39m \u001b[39m0\u001b[39m:\n\u001b[0;32m--> 880\u001b[0m         \u001b[39mreturn\u001b[39;00m \u001b[39mself\u001b[39;49m\u001b[39m.\u001b[39;49m_retry_request(\n\u001b[1;32m    881\u001b[0m             options,\n\u001b[1;32m    882\u001b[0m             cast_to,\n\u001b[1;32m    883\u001b[0m             retries,\n\u001b[1;32m    884\u001b[0m             stream\u001b[39m=\u001b[39;49mstream,\n\u001b[1;32m    885\u001b[0m             stream_cls\u001b[39m=\u001b[39;49mstream_cls,\n\u001b[1;32m    886\u001b[0m         )\n\u001b[1;32m    887\u001b[0m     \u001b[39mraise\u001b[39;00m APITimeoutError(request\u001b[39m=\u001b[39mrequest) \u001b[39mfrom\u001b[39;00m \u001b[39merr\u001b[39;00m\n\u001b[1;32m    888\u001b[0m \u001b[39mexcept\u001b[39;00m \u001b[39mException\u001b[39;00m \u001b[39mas\u001b[39;00m err:\n",
      "File \u001b[0;32m~/opt/anaconda3/envs/langchain/lib/python3.10/site-packages/openai/_base_client.py:925\u001b[0m, in \u001b[0;36mSyncAPIClient._retry_request\u001b[0;34m(self, options, cast_to, remaining_retries, response_headers, stream, stream_cls)\u001b[0m\n\u001b[1;32m    921\u001b[0m \u001b[39m# In a synchronous context we are blocking the entire thread. Up to the library user to run the client in a\u001b[39;00m\n\u001b[1;32m    922\u001b[0m \u001b[39m# different thread if necessary.\u001b[39;00m\n\u001b[1;32m    923\u001b[0m time\u001b[39m.\u001b[39msleep(timeout)\n\u001b[0;32m--> 925\u001b[0m \u001b[39mreturn\u001b[39;00m \u001b[39mself\u001b[39;49m\u001b[39m.\u001b[39;49m_request(\n\u001b[1;32m    926\u001b[0m     options\u001b[39m=\u001b[39;49moptions,\n\u001b[1;32m    927\u001b[0m     cast_to\u001b[39m=\u001b[39;49mcast_to,\n\u001b[1;32m    928\u001b[0m     remaining_retries\u001b[39m=\u001b[39;49mremaining,\n\u001b[1;32m    929\u001b[0m     stream\u001b[39m=\u001b[39;49mstream,\n\u001b[1;32m    930\u001b[0m     stream_cls\u001b[39m=\u001b[39;49mstream_cls,\n\u001b[1;32m    931\u001b[0m )\n",
      "File \u001b[0;32m~/opt/anaconda3/envs/langchain/lib/python3.10/site-packages/openai/_base_client.py:880\u001b[0m, in \u001b[0;36mSyncAPIClient._request\u001b[0;34m(self, cast_to, options, remaining_retries, stream, stream_cls)\u001b[0m\n\u001b[1;32m    878\u001b[0m \u001b[39mexcept\u001b[39;00m httpx\u001b[39m.\u001b[39mTimeoutException \u001b[39mas\u001b[39;00m err:\n\u001b[1;32m    879\u001b[0m     \u001b[39mif\u001b[39;00m retries \u001b[39m>\u001b[39m \u001b[39m0\u001b[39m:\n\u001b[0;32m--> 880\u001b[0m         \u001b[39mreturn\u001b[39;00m \u001b[39mself\u001b[39;49m\u001b[39m.\u001b[39;49m_retry_request(\n\u001b[1;32m    881\u001b[0m             options,\n\u001b[1;32m    882\u001b[0m             cast_to,\n\u001b[1;32m    883\u001b[0m             retries,\n\u001b[1;32m    884\u001b[0m             stream\u001b[39m=\u001b[39;49mstream,\n\u001b[1;32m    885\u001b[0m             stream_cls\u001b[39m=\u001b[39;49mstream_cls,\n\u001b[1;32m    886\u001b[0m         )\n\u001b[1;32m    887\u001b[0m     \u001b[39mraise\u001b[39;00m APITimeoutError(request\u001b[39m=\u001b[39mrequest) \u001b[39mfrom\u001b[39;00m \u001b[39merr\u001b[39;00m\n\u001b[1;32m    888\u001b[0m \u001b[39mexcept\u001b[39;00m \u001b[39mException\u001b[39;00m \u001b[39mas\u001b[39;00m err:\n",
      "File \u001b[0;32m~/opt/anaconda3/envs/langchain/lib/python3.10/site-packages/openai/_base_client.py:925\u001b[0m, in \u001b[0;36mSyncAPIClient._retry_request\u001b[0;34m(self, options, cast_to, remaining_retries, response_headers, stream, stream_cls)\u001b[0m\n\u001b[1;32m    921\u001b[0m \u001b[39m# In a synchronous context we are blocking the entire thread. Up to the library user to run the client in a\u001b[39;00m\n\u001b[1;32m    922\u001b[0m \u001b[39m# different thread if necessary.\u001b[39;00m\n\u001b[1;32m    923\u001b[0m time\u001b[39m.\u001b[39msleep(timeout)\n\u001b[0;32m--> 925\u001b[0m \u001b[39mreturn\u001b[39;00m \u001b[39mself\u001b[39;49m\u001b[39m.\u001b[39;49m_request(\n\u001b[1;32m    926\u001b[0m     options\u001b[39m=\u001b[39;49moptions,\n\u001b[1;32m    927\u001b[0m     cast_to\u001b[39m=\u001b[39;49mcast_to,\n\u001b[1;32m    928\u001b[0m     remaining_retries\u001b[39m=\u001b[39;49mremaining,\n\u001b[1;32m    929\u001b[0m     stream\u001b[39m=\u001b[39;49mstream,\n\u001b[1;32m    930\u001b[0m     stream_cls\u001b[39m=\u001b[39;49mstream_cls,\n\u001b[1;32m    931\u001b[0m )\n",
      "File \u001b[0;32m~/opt/anaconda3/envs/langchain/lib/python3.10/site-packages/openai/_base_client.py:887\u001b[0m, in \u001b[0;36mSyncAPIClient._request\u001b[0;34m(self, cast_to, options, remaining_retries, stream, stream_cls)\u001b[0m\n\u001b[1;32m    879\u001b[0m     \u001b[39mif\u001b[39;00m retries \u001b[39m>\u001b[39m \u001b[39m0\u001b[39m:\n\u001b[1;32m    880\u001b[0m         \u001b[39mreturn\u001b[39;00m \u001b[39mself\u001b[39m\u001b[39m.\u001b[39m_retry_request(\n\u001b[1;32m    881\u001b[0m             options,\n\u001b[1;32m    882\u001b[0m             cast_to,\n\u001b[0;32m   (...)\u001b[0m\n\u001b[1;32m    885\u001b[0m             stream_cls\u001b[39m=\u001b[39mstream_cls,\n\u001b[1;32m    886\u001b[0m         )\n\u001b[0;32m--> 887\u001b[0m     \u001b[39mraise\u001b[39;00m APITimeoutError(request\u001b[39m=\u001b[39mrequest) \u001b[39mfrom\u001b[39;00m \u001b[39merr\u001b[39;00m\n\u001b[1;32m    888\u001b[0m \u001b[39mexcept\u001b[39;00m \u001b[39mException\u001b[39;00m \u001b[39mas\u001b[39;00m err:\n\u001b[1;32m    889\u001b[0m     \u001b[39mif\u001b[39;00m retries \u001b[39m>\u001b[39m \u001b[39m0\u001b[39m:\n",
      "\u001b[0;31mAPITimeoutError\u001b[0m: Request timed out."
     ]
    }
   ],
   "source": [
    "from openai import OpenAI\n",
    "client = OpenAI()\n",
    "\n",
    "audio_file = open(\"speech.mp3\", \"rb\")\n",
    "\n",
    "transcript = client.audio.transcriptions.create(\n",
    "    model=\"whisper-1\", # ID of the model to use. Only whisper-1 is currently available.\n",
    "    file=audio_file\n",
    ")\n"
   ]
  },
  {
   "cell_type": "markdown",
   "metadata": {},
   "source": [
    "# 创建 translation"
   ]
  },
  {
   "cell_type": "code",
   "execution_count": null,
   "metadata": {},
   "outputs": [],
   "source": [
    "from openai import OpenAI\n",
    "client = OpenAI()\n",
    "\n",
    "audio_file = open(\"speech.mp3\", \"rb\")\n",
    "transcript = client.audio.translations.create(\n",
    "  model=\"whisper-1\",  # ID of the model to use. Only whisper-1 is currently available.\n",
    "  file=audio_file # The audio file object (not file name) translate, in one of these formats: flac, mp3, mp4, mpeg, mpga, m4a, ogg, wav, or webm.\n",
    ")\n"
   ]
  },
  {
   "cell_type": "code",
   "execution_count": null,
   "metadata": {},
   "outputs": [],
   "source": []
  },
  {
   "cell_type": "code",
   "execution_count": null,
   "metadata": {},
   "outputs": [],
   "source": []
  },
  {
   "cell_type": "code",
   "execution_count": null,
   "metadata": {},
   "outputs": [],
   "source": []
  },
  {
   "cell_type": "code",
   "execution_count": null,
   "metadata": {},
   "outputs": [],
   "source": []
  }
 ],
 "metadata": {
  "kernelspec": {
   "display_name": "langchain",
   "language": "python",
   "name": "python3"
  },
  "language_info": {
   "codemirror_mode": {
    "name": "ipython",
    "version": 3
   },
   "file_extension": ".py",
   "mimetype": "text/x-python",
   "name": "python",
   "nbconvert_exporter": "python",
   "pygments_lexer": "ipython3",
   "version": "3.10.11"
  }
 },
 "nbformat": 4,
 "nbformat_minor": 2
}
